[2025-06-18 16:09:35,539] ERROR [FUNC:- log_exception] 
Traceback (most recent call last):
  File "C:\Users\Sagacity\AppData\Local\Programs\Python\Python312\Lib\site-packages\django\core\handlers\base.py", line 197, in _get_response
    response = wrapped_callback(request, *callback_args, **callback_kwargs)
               ^^^^^^^^^^^^^^^^^^^^^^^^^^^^^^^^^^^^^^^^^^^^^^^^^^^^^^^^^^^^
  File "C:\Users\Sagacity\AppData\Local\Programs\Python\Python312\Lib\site-packages\django\views\decorators\csrf.py", line 65, in _view_wrapper
    return view_func(request, *args, **kwargs)
           ^^^^^^^^^^^^^^^^^^^^^^^^^^^^^^^^^^^
  File "C:\Users\Sagacity\AppData\Local\Programs\Python\Python312\Lib\site-packages\rest_framework\viewsets.py", line 125, in view
    return self.dispatch(request, *args, **kwargs)
           ^^^^^^^^^^^^^^^^^^^^^^^^^^^^^^^^^^^^^^^
  File "C:\Users\Sagacity\AppData\Local\Programs\Python\Python312\Lib\site-packages\rest_framework\views.py", line 515, in dispatch
    response = self.handle_exception(exc)
               ^^^^^^^^^^^^^^^^^^^^^^^^^^
  File "C:\Users\Sagacity\AppData\Local\Programs\Python\Python312\Lib\site-packages\rest_framework\views.py", line 475, in handle_exception
    self.raise_uncaught_exception(exc)
  File "C:\Users\Sagacity\AppData\Local\Programs\Python\Python312\Lib\site-packages\rest_framework\views.py", line 486, in raise_uncaught_exception
    raise exc
  File "C:\Users\Sagacity\AppData\Local\Programs\Python\Python312\Lib\site-packages\rest_framework\views.py", line 512, in dispatch
    response = handler(request, *args, **kwargs)
               ^^^^^^^^^^^^^^^^^^^^^^^^^^^^^^^^^
  File "C:\Users\Sagacity\Desktop\Project\transportation-management-system\backend\transportation-management-system\auth_user\views\auth.py", line 94, in create
    return super().create(request, *args, **kwargs)
           ^^^^^^^^^^^^^^^^^^^^^^^^^^^^^^^^^^^^^^^^
  File "C:\Users\Sagacity\Desktop\Project\transportation-management-system\backend\transportation-management-system\base\views\create.py", line 127, in create
    data = self.pre_save(data=data, request=request)
           ^^^^^^^^^^^^^^^^^^^^^^^^^^^^^^^^^^^^^^^^^
  File "C:\Users\Sagacity\Desktop\Project\transportation-management-system\backend\transportation-management-system\auth_user\views\auth.py", line 60, in pre_save
    cache.set(f"user_token:{user_obj.id}", token)
                            ^^^^^^^^^^^
AttributeError: 'User' object has no attribute 'id'

---------------------------------------------------------------------------------------------------------------------
[2025-07-09 15:52:01,818] INFO [FUNC:- handle] 
Loading data from files...
---------------------------------------------------------------------------------------------------------------------
[2025-07-09 15:52:02,053] INFO [FUNC:- handle] 
Data loaded successfully.
---------------------------------------------------------------------------------------------------------------------
[2025-07-09 15:53:28,383] INFO [FUNC:- handle] 
Loading data from files...
---------------------------------------------------------------------------------------------------------------------
[2025-07-09 15:53:28,512] INFO [FUNC:- handle] 
Data loaded successfully.
---------------------------------------------------------------------------------------------------------------------
[2025-07-09 15:54:34,241] INFO [FUNC:- handle] 
Loading data from files...
---------------------------------------------------------------------------------------------------------------------
[2025-07-09 15:54:34,419] INFO [FUNC:- handle] 
Data loaded successfully.
---------------------------------------------------------------------------------------------------------------------
[2025-07-09 15:57:54,169] INFO [FUNC:- handle] 
Loading data from files...
---------------------------------------------------------------------------------------------------------------------
[2025-07-09 15:57:54,349] INFO [FUNC:- handle] 
Data loaded successfully.
---------------------------------------------------------------------------------------------------------------------
[2025-07-09 17:44:51,197] ERROR [FUNC:- log_exception] 
Traceback (most recent call last):
  File "C:\Users\Sagacity\AppData\Local\Programs\Python\Python312\Lib\site-packages\django\core\handlers\base.py", line 197, in _get_response
    response = wrapped_callback(request, *callback_args, **callback_kwargs)
               ^^^^^^^^^^^^^^^^^^^^^^^^^^^^^^^^^^^^^^^^^^^^^^^^^^^^^^^^^^^^
  File "C:\Users\Sagacity\AppData\Local\Programs\Python\Python312\Lib\site-packages\django\views\decorators\csrf.py", line 65, in _view_wrapper
    return view_func(request, *args, **kwargs)
           ^^^^^^^^^^^^^^^^^^^^^^^^^^^^^^^^^^^
  File "C:\Users\Sagacity\AppData\Local\Programs\Python\Python312\Lib\site-packages\rest_framework\viewsets.py", line 124, in view
    return self.dispatch(request, *args, **kwargs)
           ^^^^^^^^^^^^^^^^^^^^^^^^^^^^^^^^^^^^^^^
  File "C:\Users\Sagacity\AppData\Local\Programs\Python\Python312\Lib\site-packages\rest_framework\views.py", line 509, in dispatch
    response = self.handle_exception(exc)
               ^^^^^^^^^^^^^^^^^^^^^^^^^^
  File "C:\Users\Sagacity\AppData\Local\Programs\Python\Python312\Lib\site-packages\rest_framework\views.py", line 469, in handle_exception
    self.raise_uncaught_exception(exc)
  File "C:\Users\Sagacity\AppData\Local\Programs\Python\Python312\Lib\site-packages\rest_framework\views.py", line 480, in raise_uncaught_exception
    raise exc
  File "C:\Users\Sagacity\AppData\Local\Programs\Python\Python312\Lib\site-packages\rest_framework\views.py", line 506, in dispatch
    response = handler(request, *args, **kwargs)
               ^^^^^^^^^^^^^^^^^^^^^^^^^^^^^^^^^
  File "C:\Users\Sagacity\Desktop\Project\TMS\transportation-management-system-backend\customer\views\customer.py", line 84, in list_all
    return super().list_all(request, *args, **kwargs)
           ^^^^^^^^^^^^^^^^^^^^^^^^^^^^^^^^^^^^^^^^^^
  File "C:\Users\Sagacity\Desktop\Project\TMS\transportation-management-system-backend\base\views\list.py", line 32, in list_all
    self.get_with_pagination(request, query)
  File "C:\Users\Sagacity\Desktop\Project\TMS\transportation-management-system-backend\base\views\list.py", line 71, in get_with_pagination
    "page": query_params["page"],
            ~~~~~~~~~~~~^^^^^^^^
KeyError: 'page'

---------------------------------------------------------------------------------------------------------------------
[2025-07-09 18:01:44,847] ERROR [FUNC:- log_exception] 
Traceback (most recent call last):
  File "C:\Users\Sagacity\AppData\Local\Programs\Python\Python312\Lib\site-packages\django\core\handlers\base.py", line 197, in _get_response
    response = wrapped_callback(request, *callback_args, **callback_kwargs)
               ^^^^^^^^^^^^^^^^^^^^^^^^^^^^^^^^^^^^^^^^^^^^^^^^^^^^^^^^^^^^
  File "C:\Users\Sagacity\AppData\Local\Programs\Python\Python312\Lib\site-packages\django\views\decorators\csrf.py", line 65, in _view_wrapper
    return view_func(request, *args, **kwargs)
           ^^^^^^^^^^^^^^^^^^^^^^^^^^^^^^^^^^^
  File "C:\Users\Sagacity\AppData\Local\Programs\Python\Python312\Lib\site-packages\rest_framework\viewsets.py", line 124, in view
    return self.dispatch(request, *args, **kwargs)
           ^^^^^^^^^^^^^^^^^^^^^^^^^^^^^^^^^^^^^^^
  File "C:\Users\Sagacity\AppData\Local\Programs\Python\Python312\Lib\site-packages\rest_framework\views.py", line 509, in dispatch
    response = self.handle_exception(exc)
               ^^^^^^^^^^^^^^^^^^^^^^^^^^
  File "C:\Users\Sagacity\AppData\Local\Programs\Python\Python312\Lib\site-packages\rest_framework\views.py", line 469, in handle_exception
    self.raise_uncaught_exception(exc)
  File "C:\Users\Sagacity\AppData\Local\Programs\Python\Python312\Lib\site-packages\rest_framework\views.py", line 480, in raise_uncaught_exception
    raise exc
  File "C:\Users\Sagacity\AppData\Local\Programs\Python\Python312\Lib\site-packages\rest_framework\views.py", line 506, in dispatch
    response = handler(request, *args, **kwargs)
               ^^^^^^^^^^^^^^^^^^^^^^^^^^^^^^^^^
  File "C:\Users\Sagacity\Desktop\Project\TMS\transportation-management-system-backend\customer\views\customer.py", line 84, in list_all
    return super().list_all(request, *args, **kwargs)
           ^^^^^^^^^^^^^^^^^^^^^^^^^^^^^^^^^^^^^^^^^^
  File "C:\Users\Sagacity\Desktop\Project\TMS\transportation-management-system-backend\base\views\list.py", line 32, in list_all
    self.get_with_pagination(request, query)
  File "C:\Users\Sagacity\Desktop\Project\TMS\transportation-management-system-backend\base\views\list.py", line 71, in get_with_pagination
    "page": query_params["page"],
            ~~~~~~~~~~~~^^^^^^^^
KeyError: 'page'

---------------------------------------------------------------------------------------------------------------------
[2025-07-10 12:23:55,127] ERROR [FUNC:- log_exception] 
Traceback (most recent call last):
  File "C:\Users\Sagacity\AppData\Local\Programs\Python\Python312\Lib\site-packages\django\core\handlers\base.py", line 197, in _get_response
    response = wrapped_callback(request, *callback_args, **callback_kwargs)
               ^^^^^^^^^^^^^^^^^^^^^^^^^^^^^^^^^^^^^^^^^^^^^^^^^^^^^^^^^^^^
  File "C:\Users\Sagacity\AppData\Local\Programs\Python\Python312\Lib\site-packages\django\views\decorators\csrf.py", line 65, in _view_wrapper
    return view_func(request, *args, **kwargs)
           ^^^^^^^^^^^^^^^^^^^^^^^^^^^^^^^^^^^
  File "C:\Users\Sagacity\AppData\Local\Programs\Python\Python312\Lib\site-packages\rest_framework\viewsets.py", line 124, in view
    return self.dispatch(request, *args, **kwargs)
           ^^^^^^^^^^^^^^^^^^^^^^^^^^^^^^^^^^^^^^^
  File "C:\Users\Sagacity\AppData\Local\Programs\Python\Python312\Lib\site-packages\rest_framework\views.py", line 509, in dispatch
    response = self.handle_exception(exc)
               ^^^^^^^^^^^^^^^^^^^^^^^^^^
  File "C:\Users\Sagacity\AppData\Local\Programs\Python\Python312\Lib\site-packages\rest_framework\views.py", line 469, in handle_exception
    self.raise_uncaught_exception(exc)
  File "C:\Users\Sagacity\AppData\Local\Programs\Python\Python312\Lib\site-packages\rest_framework\views.py", line 480, in raise_uncaught_exception
    raise exc
  File "C:\Users\Sagacity\AppData\Local\Programs\Python\Python312\Lib\site-packages\rest_framework\views.py", line 506, in dispatch
    response = handler(request, *args, **kwargs)
               ^^^^^^^^^^^^^^^^^^^^^^^^^^^^^^^^^
  File "C:\Users\Sagacity\Desktop\Project\TMS\transportation-management-system-backend\invoice\views\invoice.py", line 123, in list_all
    return super().list_all(request, *args, **kwargs)
           ^^^^^^^^^^^^^^^^^^^^^^^^^^^^^^^^^^^^^^^^^^
  File "C:\Users\Sagacity\Desktop\Project\TMS\transportation-management-system-backend\base\views\list.py", line 85, in list_all
    return self.get_with_pagination(request, query)
           ^^^^^^^^^^^^^^^^^^^^^^^^^^^^^^^^^^^^^^^^
  File "C:\Users\Sagacity\Desktop\Project\TMS\transportation-management-system-backend\base\views\list.py", line 146, in get_with_pagination
    objects, pagination = self.manager.list_with_pagination(
                          ^^^^^^^^^^^^^^^^^^^^^^^^^^^^^^^^^^
  File "C:\Users\Sagacity\Desktop\Project\TMS\transportation-management-system-backend\base\db_access\manager.py", line 254, in list_with_pagination
    objects = self.list(query=query, only=only, order_by=order_by)
              ^^^^^^^^^^^^^^^^^^^^^^^^^^^^^^^^^^^^^^^^^^^^^^^^^^^^
  File "C:\Users\Sagacity\Desktop\Project\TMS\transportation-management-system-backend\base\db_access\manager.py", line 213, in list
    objects = self.__parse_query(query=query)
              ^^^^^^^^^^^^^^^^^^^^^^^^^^^^^^^
  File "C:\Users\Sagacity\Desktop\Project\TMS\transportation-management-system-backend\base\db_access\manager.py", line 168, in __parse_query
    objects = self.model.objects.filter(self.query_builder.build_query(query))
              ^^^^^^^^^^^^^^^^^^^^^^^^^^^^^^^^^^^^^^^^^^^^^^^^^^^^^^^^^^^^^^^^
  File "C:\Users\Sagacity\AppData\Local\Programs\Python\Python312\Lib\site-packages\django\db\models\manager.py", line 87, in manager_method
    return getattr(self.get_queryset(), name)(*args, **kwargs)
           ^^^^^^^^^^^^^^^^^^^^^^^^^^^^^^^^^^^^^^^^^^^^^^^^^^^
  File "C:\Users\Sagacity\AppData\Local\Programs\Python\Python312\Lib\site-packages\django\db\models\query.py", line 1476, in filter
    return self._filter_or_exclude(False, args, kwargs)
           ^^^^^^^^^^^^^^^^^^^^^^^^^^^^^^^^^^^^^^^^^^^^
  File "C:\Users\Sagacity\AppData\Local\Programs\Python\Python312\Lib\site-packages\django\db\models\query.py", line 1494, in _filter_or_exclude
    clone._filter_or_exclude_inplace(negate, args, kwargs)
  File "C:\Users\Sagacity\AppData\Local\Programs\Python\Python312\Lib\site-packages\django\db\models\query.py", line 1501, in _filter_or_exclude_inplace
    self._query.add_q(Q(*args, **kwargs))
  File "C:\Users\Sagacity\AppData\Local\Programs\Python\Python312\Lib\site-packages\django\db\models\sql\query.py", line 1613, in add_q
    clause, _ = self._add_q(q_object, self.used_aliases)
                ^^^^^^^^^^^^^^^^^^^^^^^^^^^^^^^^^^^^^^^^
  File "C:\Users\Sagacity\AppData\Local\Programs\Python\Python312\Lib\site-packages\django\db\models\sql\query.py", line 1645, in _add_q
    child_clause, needed_inner = self.build_filter(
                                 ^^^^^^^^^^^^^^^^^^
  File "C:\Users\Sagacity\AppData\Local\Programs\Python\Python312\Lib\site-packages\django\db\models\sql\query.py", line 1472, in build_filter
    return self._add_q(
           ^^^^^^^^^^^^
  File "C:\Users\Sagacity\AppData\Local\Programs\Python\Python312\Lib\site-packages\django\db\models\sql\query.py", line 1645, in _add_q
    child_clause, needed_inner = self.build_filter(
                                 ^^^^^^^^^^^^^^^^^^
  File "C:\Users\Sagacity\AppData\Local\Programs\Python\Python312\Lib\site-packages\django\db\models\sql\query.py", line 1559, in build_filter
    condition = self.build_lookup(lookups, col, value)
                ^^^^^^^^^^^^^^^^^^^^^^^^^^^^^^^^^^^^^^
  File "C:\Users\Sagacity\AppData\Local\Programs\Python\Python312\Lib\site-packages\django\db\models\sql\query.py", line 1383, in build_lookup
    lhs = self.try_transform(lhs, lookup_name)
          ^^^^^^^^^^^^^^^^^^^^^^^^^^^^^^^^^^^^
  File "C:\Users\Sagacity\AppData\Local\Programs\Python\Python312\Lib\site-packages\django\db\models\sql\query.py", line 1427, in try_transform
    raise FieldError(
django.core.exceptions.FieldError: Unsupported lookup 'name' for ForeignKey or join on the field not permitted.

---------------------------------------------------------------------------------------------------------------------
[2025-07-10 12:25:01,189] ERROR [FUNC:- log_exception] 
Traceback (most recent call last):
  File "C:\Users\Sagacity\AppData\Local\Programs\Python\Python312\Lib\site-packages\django\core\handlers\base.py", line 197, in _get_response
    response = wrapped_callback(request, *callback_args, **callback_kwargs)
               ^^^^^^^^^^^^^^^^^^^^^^^^^^^^^^^^^^^^^^^^^^^^^^^^^^^^^^^^^^^^
  File "C:\Users\Sagacity\AppData\Local\Programs\Python\Python312\Lib\site-packages\django\views\decorators\csrf.py", line 65, in _view_wrapper
    return view_func(request, *args, **kwargs)
           ^^^^^^^^^^^^^^^^^^^^^^^^^^^^^^^^^^^
  File "C:\Users\Sagacity\AppData\Local\Programs\Python\Python312\Lib\site-packages\rest_framework\viewsets.py", line 124, in view
    return self.dispatch(request, *args, **kwargs)
           ^^^^^^^^^^^^^^^^^^^^^^^^^^^^^^^^^^^^^^^
  File "C:\Users\Sagacity\AppData\Local\Programs\Python\Python312\Lib\site-packages\rest_framework\views.py", line 509, in dispatch
    response = self.handle_exception(exc)
               ^^^^^^^^^^^^^^^^^^^^^^^^^^
  File "C:\Users\Sagacity\AppData\Local\Programs\Python\Python312\Lib\site-packages\rest_framework\views.py", line 469, in handle_exception
    self.raise_uncaught_exception(exc)
  File "C:\Users\Sagacity\AppData\Local\Programs\Python\Python312\Lib\site-packages\rest_framework\views.py", line 480, in raise_uncaught_exception
    raise exc
  File "C:\Users\Sagacity\AppData\Local\Programs\Python\Python312\Lib\site-packages\rest_framework\views.py", line 506, in dispatch
    response = handler(request, *args, **kwargs)
               ^^^^^^^^^^^^^^^^^^^^^^^^^^^^^^^^^
  File "C:\Users\Sagacity\Desktop\Project\TMS\transportation-management-system-backend\invoice\views\invoice.py", line 123, in list_all
    return super().list_all(request, *args, **kwargs)
           ^^^^^^^^^^^^^^^^^^^^^^^^^^^^^^^^^^^^^^^^^^
  File "C:\Users\Sagacity\Desktop\Project\TMS\transportation-management-system-backend\base\views\list.py", line 85, in list_all
    return self.get_with_pagination(request, query)
           ^^^^^^^^^^^^^^^^^^^^^^^^^^^^^^^^^^^^^^^^
  File "C:\Users\Sagacity\Desktop\Project\TMS\transportation-management-system-backend\base\views\list.py", line 146, in get_with_pagination
    objects, pagination = self.manager.list_with_pagination(
                          ^^^^^^^^^^^^^^^^^^^^^^^^^^^^^^^^^^
  File "C:\Users\Sagacity\Desktop\Project\TMS\transportation-management-system-backend\base\db_access\manager.py", line 254, in list_with_pagination
    objects = self.list(query=query, only=only, order_by=order_by)
              ^^^^^^^^^^^^^^^^^^^^^^^^^^^^^^^^^^^^^^^^^^^^^^^^^^^^
  File "C:\Users\Sagacity\Desktop\Project\TMS\transportation-management-system-backend\base\db_access\manager.py", line 213, in list
    objects = self.__parse_query(query=query)
              ^^^^^^^^^^^^^^^^^^^^^^^^^^^^^^^
  File "C:\Users\Sagacity\Desktop\Project\TMS\transportation-management-system-backend\base\db_access\manager.py", line 168, in __parse_query
    objects = self.model.objects.filter(self.query_builder.build_query(query))
              ^^^^^^^^^^^^^^^^^^^^^^^^^^^^^^^^^^^^^^^^^^^^^^^^^^^^^^^^^^^^^^^^
  File "C:\Users\Sagacity\AppData\Local\Programs\Python\Python312\Lib\site-packages\django\db\models\manager.py", line 87, in manager_method
    return getattr(self.get_queryset(), name)(*args, **kwargs)
           ^^^^^^^^^^^^^^^^^^^^^^^^^^^^^^^^^^^^^^^^^^^^^^^^^^^
  File "C:\Users\Sagacity\AppData\Local\Programs\Python\Python312\Lib\site-packages\django\db\models\query.py", line 1476, in filter
    return self._filter_or_exclude(False, args, kwargs)
           ^^^^^^^^^^^^^^^^^^^^^^^^^^^^^^^^^^^^^^^^^^^^
  File "C:\Users\Sagacity\AppData\Local\Programs\Python\Python312\Lib\site-packages\django\db\models\query.py", line 1494, in _filter_or_exclude
    clone._filter_or_exclude_inplace(negate, args, kwargs)
  File "C:\Users\Sagacity\AppData\Local\Programs\Python\Python312\Lib\site-packages\django\db\models\query.py", line 1501, in _filter_or_exclude_inplace
    self._query.add_q(Q(*args, **kwargs))
  File "C:\Users\Sagacity\AppData\Local\Programs\Python\Python312\Lib\site-packages\django\db\models\sql\query.py", line 1613, in add_q
    clause, _ = self._add_q(q_object, self.used_aliases)
                ^^^^^^^^^^^^^^^^^^^^^^^^^^^^^^^^^^^^^^^^
  File "C:\Users\Sagacity\AppData\Local\Programs\Python\Python312\Lib\site-packages\django\db\models\sql\query.py", line 1645, in _add_q
    child_clause, needed_inner = self.build_filter(
                                 ^^^^^^^^^^^^^^^^^^
  File "C:\Users\Sagacity\AppData\Local\Programs\Python\Python312\Lib\site-packages\django\db\models\sql\query.py", line 1472, in build_filter
    return self._add_q(
           ^^^^^^^^^^^^
  File "C:\Users\Sagacity\AppData\Local\Programs\Python\Python312\Lib\site-packages\django\db\models\sql\query.py", line 1645, in _add_q
    child_clause, needed_inner = self.build_filter(
                                 ^^^^^^^^^^^^^^^^^^
  File "C:\Users\Sagacity\AppData\Local\Programs\Python\Python312\Lib\site-packages\django\db\models\sql\query.py", line 1495, in build_filter
    lookups, parts, reffed_expression = self.solve_lookup_type(arg, summarize)
                                        ^^^^^^^^^^^^^^^^^^^^^^^^^^^^^^^^^^^^^^
  File "C:\Users\Sagacity\AppData\Local\Programs\Python\Python312\Lib\site-packages\django\db\models\sql\query.py", line 1307, in solve_lookup_type
    _, field, _, lookup_parts = self.names_to_path(lookup_splitted, self.get_meta())
                                ^^^^^^^^^^^^^^^^^^^^^^^^^^^^^^^^^^^^^^^^^^^^^^^^^^^^
  File "C:\Users\Sagacity\AppData\Local\Programs\Python\Python312\Lib\site-packages\django\db\models\sql\query.py", line 1772, in names_to_path
    raise FieldError(
django.core.exceptions.FieldError: Cannot resolve keyword 'vehicle_vehicle' into field. Choices are: created_by, created_dtm, customer, customer_id, date, deleted_dtm, delivery_address, invoice_id, is_active, is_deleted, loading_address, rate, status, total, updated_by, updated_dtm, vehicle, vehicle_id, weight

---------------------------------------------------------------------------------------------------------------------
[2025-07-10 18:14:05,111] ERROR [FUNC:- log_exception] 
Traceback (most recent call last):
  File "C:\Users\Sagacity\AppData\Local\Programs\Python\Python312\Lib\site-packages\django\core\handlers\base.py", line 197, in _get_response
    response = wrapped_callback(request, *callback_args, **callback_kwargs)
               ^^^^^^^^^^^^^^^^^^^^^^^^^^^^^^^^^^^^^^^^^^^^^^^^^^^^^^^^^^^^
  File "C:\Users\Sagacity\AppData\Local\Programs\Python\Python312\Lib\site-packages\django\views\decorators\csrf.py", line 65, in _view_wrapper
    return view_func(request, *args, **kwargs)
           ^^^^^^^^^^^^^^^^^^^^^^^^^^^^^^^^^^^
  File "C:\Users\Sagacity\AppData\Local\Programs\Python\Python312\Lib\site-packages\rest_framework\viewsets.py", line 124, in view
    return self.dispatch(request, *args, **kwargs)
           ^^^^^^^^^^^^^^^^^^^^^^^^^^^^^^^^^^^^^^^
  File "C:\Users\Sagacity\AppData\Local\Programs\Python\Python312\Lib\site-packages\rest_framework\views.py", line 509, in dispatch
    response = self.handle_exception(exc)
               ^^^^^^^^^^^^^^^^^^^^^^^^^^
  File "C:\Users\Sagacity\AppData\Local\Programs\Python\Python312\Lib\site-packages\rest_framework\views.py", line 469, in handle_exception
    self.raise_uncaught_exception(exc)
  File "C:\Users\Sagacity\AppData\Local\Programs\Python\Python312\Lib\site-packages\rest_framework\views.py", line 480, in raise_uncaught_exception
    raise exc
  File "C:\Users\Sagacity\AppData\Local\Programs\Python\Python312\Lib\site-packages\rest_framework\views.py", line 506, in dispatch
    response = handler(request, *args, **kwargs)
               ^^^^^^^^^^^^^^^^^^^^^^^^^^^^^^^^^
  File "C:\Users\Sagacity\Desktop\Project\TMS\transportation-management-system-backend\invoice\views\invoice.py", line 106, in create
    return super().create(request, *args, **kwargs)
           ^^^^^^^^^^^^^^^^^^^^^^^^^^^^^^^^^^^^^^^^
  File "C:\Users\Sagacity\Desktop\Project\TMS\transportation-management-system-backend\base\views\create.py", line 129, in create
    obj = self.manager.create(data, many=self.many)
          ^^^^^^^^^^^^^^^^^^^^^^^^^^^^^^^^^^^^^^^^^
  File "C:\Users\Sagacity\Desktop\Project\TMS\transportation-management-system-backend\base\db_access\manager.py", line 343, in create
    return self.model.objects.create(**data)
           ^^^^^^^^^^^^^^^^^^^^^^^^^^^^^^^^^
  File "C:\Users\Sagacity\AppData\Local\Programs\Python\Python312\Lib\site-packages\django\db\models\manager.py", line 87, in manager_method
    return getattr(self.get_queryset(), name)(*args, **kwargs)
           ^^^^^^^^^^^^^^^^^^^^^^^^^^^^^^^^^^^^^^^^^^^^^^^^^^^
  File "C:\Users\Sagacity\AppData\Local\Programs\Python\Python312\Lib\site-packages\django\db\models\query.py", line 679, in create
    obj.save(force_insert=True, using=self.db)
  File "C:\Users\Sagacity\AppData\Local\Programs\Python\Python312\Lib\site-packages\django\db\models\base.py", line 822, in save
    self.save_base(
  File "C:\Users\Sagacity\AppData\Local\Programs\Python\Python312\Lib\site-packages\django\db\models\base.py", line 924, in save_base
    post_save.send(
  File "C:\Users\Sagacity\AppData\Local\Programs\Python\Python312\Lib\site-packages\django\dispatch\dispatcher.py", line 189, in send
    response = receiver(signal=self, sender=sender, **named)
               ^^^^^^^^^^^^^^^^^^^^^^^^^^^^^^^^^^^^^^^^^^^^^
  File "C:\Users\Sagacity\Desktop\Project\TMS\transportation-management-system-backend\invoice\db_access\invoice.py", line 34, in send_notification_on_quotation_movement
    "invoice_number": instance.invoice_number,
                      ^^^^^^^^^^^^^^^^^^^^^^^
AttributeError: 'Invoice' object has no attribute 'invoice_number'

---------------------------------------------------------------------------------------------------------------------
[2025-07-10 18:15:31,382] ERROR [FUNC:- log_exception] 
Traceback (most recent call last):
  File "C:\Users\Sagacity\AppData\Local\Programs\Python\Python312\Lib\site-packages\django\core\handlers\base.py", line 197, in _get_response
    response = wrapped_callback(request, *callback_args, **callback_kwargs)
               ^^^^^^^^^^^^^^^^^^^^^^^^^^^^^^^^^^^^^^^^^^^^^^^^^^^^^^^^^^^^
  File "C:\Users\Sagacity\AppData\Local\Programs\Python\Python312\Lib\site-packages\django\views\decorators\csrf.py", line 65, in _view_wrapper
    return view_func(request, *args, **kwargs)
           ^^^^^^^^^^^^^^^^^^^^^^^^^^^^^^^^^^^
  File "C:\Users\Sagacity\AppData\Local\Programs\Python\Python312\Lib\site-packages\rest_framework\viewsets.py", line 124, in view
    return self.dispatch(request, *args, **kwargs)
           ^^^^^^^^^^^^^^^^^^^^^^^^^^^^^^^^^^^^^^^
  File "C:\Users\Sagacity\AppData\Local\Programs\Python\Python312\Lib\site-packages\rest_framework\views.py", line 509, in dispatch
    response = self.handle_exception(exc)
               ^^^^^^^^^^^^^^^^^^^^^^^^^^
  File "C:\Users\Sagacity\AppData\Local\Programs\Python\Python312\Lib\site-packages\rest_framework\views.py", line 469, in handle_exception
    self.raise_uncaught_exception(exc)
  File "C:\Users\Sagacity\AppData\Local\Programs\Python\Python312\Lib\site-packages\rest_framework\views.py", line 480, in raise_uncaught_exception
    raise exc
  File "C:\Users\Sagacity\AppData\Local\Programs\Python\Python312\Lib\site-packages\rest_framework\views.py", line 506, in dispatch
    response = handler(request, *args, **kwargs)
               ^^^^^^^^^^^^^^^^^^^^^^^^^^^^^^^^^
  File "C:\Users\Sagacity\Desktop\Project\TMS\transportation-management-system-backend\invoice\views\invoice.py", line 106, in create
    return super().create(request, *args, **kwargs)
           ^^^^^^^^^^^^^^^^^^^^^^^^^^^^^^^^^^^^^^^^
  File "C:\Users\Sagacity\Desktop\Project\TMS\transportation-management-system-backend\base\views\create.py", line 129, in create
    obj = self.manager.create(data, many=self.many)
          ^^^^^^^^^^^^^^^^^^^^^^^^^^^^^^^^^^^^^^^^^
  File "C:\Users\Sagacity\Desktop\Project\TMS\transportation-management-system-backend\base\db_access\manager.py", line 343, in create
    return self.model.objects.create(**data)
           ^^^^^^^^^^^^^^^^^^^^^^^^^^^^^^^^^
  File "C:\Users\Sagacity\AppData\Local\Programs\Python\Python312\Lib\site-packages\django\db\models\manager.py", line 87, in manager_method
    return getattr(self.get_queryset(), name)(*args, **kwargs)
           ^^^^^^^^^^^^^^^^^^^^^^^^^^^^^^^^^^^^^^^^^^^^^^^^^^^
  File "C:\Users\Sagacity\AppData\Local\Programs\Python\Python312\Lib\site-packages\django\db\models\query.py", line 679, in create
    obj.save(force_insert=True, using=self.db)
  File "C:\Users\Sagacity\AppData\Local\Programs\Python\Python312\Lib\site-packages\django\db\models\base.py", line 822, in save
    self.save_base(
  File "C:\Users\Sagacity\AppData\Local\Programs\Python\Python312\Lib\site-packages\django\db\models\base.py", line 924, in save_base
    post_save.send(
  File "C:\Users\Sagacity\AppData\Local\Programs\Python\Python312\Lib\site-packages\django\dispatch\dispatcher.py", line 189, in send
    response = receiver(signal=self, sender=sender, **named)
               ^^^^^^^^^^^^^^^^^^^^^^^^^^^^^^^^^^^^^^^^^^^^^
  File "C:\Users\Sagacity\Desktop\Project\TMS\transportation-management-system-backend\invoice\db_access\invoice.py", line 34, in send_notification_on_quotation_movement
    "date": instance.due_date.isoformat() if instance.due_date else None,
                                             ^^^^^^^^^^^^^^^^^
AttributeError: 'Invoice' object has no attribute 'due_date'

---------------------------------------------------------------------------------------------------------------------
[2025-07-10 18:16:01,381] ERROR [FUNC:- log_exception] 
Traceback (most recent call last):
  File "C:\Users\Sagacity\AppData\Local\Programs\Python\Python312\Lib\site-packages\django\db\backends\utils.py", line 105, in _execute
    return self.cursor.execute(sql, params)
           ^^^^^^^^^^^^^^^^^^^^^^^^^^^^^^^^
  File "C:\Users\Sagacity\AppData\Local\Programs\Python\Python312\Lib\site-packages\django\db\backends\sqlite3\base.py", line 329, in execute
    return super().execute(query, params)
           ^^^^^^^^^^^^^^^^^^^^^^^^^^^^^^
sqlite3.OperationalError: no such table: notification

The above exception was the direct cause of the following exception:

Traceback (most recent call last):
  File "C:\Users\Sagacity\AppData\Local\Programs\Python\Python312\Lib\site-packages\django\core\handlers\base.py", line 197, in _get_response
    response = wrapped_callback(request, *callback_args, **callback_kwargs)
               ^^^^^^^^^^^^^^^^^^^^^^^^^^^^^^^^^^^^^^^^^^^^^^^^^^^^^^^^^^^^
  File "C:\Users\Sagacity\AppData\Local\Programs\Python\Python312\Lib\site-packages\django\views\decorators\csrf.py", line 65, in _view_wrapper
    return view_func(request, *args, **kwargs)
           ^^^^^^^^^^^^^^^^^^^^^^^^^^^^^^^^^^^
  File "C:\Users\Sagacity\AppData\Local\Programs\Python\Python312\Lib\site-packages\rest_framework\viewsets.py", line 124, in view
    return self.dispatch(request, *args, **kwargs)
           ^^^^^^^^^^^^^^^^^^^^^^^^^^^^^^^^^^^^^^^
  File "C:\Users\Sagacity\AppData\Local\Programs\Python\Python312\Lib\site-packages\rest_framework\views.py", line 509, in dispatch
    response = self.handle_exception(exc)
               ^^^^^^^^^^^^^^^^^^^^^^^^^^
  File "C:\Users\Sagacity\AppData\Local\Programs\Python\Python312\Lib\site-packages\rest_framework\views.py", line 469, in handle_exception
    self.raise_uncaught_exception(exc)
  File "C:\Users\Sagacity\AppData\Local\Programs\Python\Python312\Lib\site-packages\rest_framework\views.py", line 480, in raise_uncaught_exception
    raise exc
  File "C:\Users\Sagacity\AppData\Local\Programs\Python\Python312\Lib\site-packages\rest_framework\views.py", line 506, in dispatch
    response = handler(request, *args, **kwargs)
               ^^^^^^^^^^^^^^^^^^^^^^^^^^^^^^^^^
  File "C:\Users\Sagacity\Desktop\Project\TMS\transportation-management-system-backend\invoice\views\invoice.py", line 106, in create
    return super().create(request, *args, **kwargs)
           ^^^^^^^^^^^^^^^^^^^^^^^^^^^^^^^^^^^^^^^^
  File "C:\Users\Sagacity\Desktop\Project\TMS\transportation-management-system-backend\base\views\create.py", line 129, in create
    obj = self.manager.create(data, many=self.many)
          ^^^^^^^^^^^^^^^^^^^^^^^^^^^^^^^^^^^^^^^^^
  File "C:\Users\Sagacity\Desktop\Project\TMS\transportation-management-system-backend\base\db_access\manager.py", line 343, in create
    return self.model.objects.create(**data)
           ^^^^^^^^^^^^^^^^^^^^^^^^^^^^^^^^^
  File "C:\Users\Sagacity\AppData\Local\Programs\Python\Python312\Lib\site-packages\django\db\models\manager.py", line 87, in manager_method
    return getattr(self.get_queryset(), name)(*args, **kwargs)
           ^^^^^^^^^^^^^^^^^^^^^^^^^^^^^^^^^^^^^^^^^^^^^^^^^^^
  File "C:\Users\Sagacity\AppData\Local\Programs\Python\Python312\Lib\site-packages\django\db\models\query.py", line 679, in create
    obj.save(force_insert=True, using=self.db)
  File "C:\Users\Sagacity\AppData\Local\Programs\Python\Python312\Lib\site-packages\django\db\models\base.py", line 822, in save
    self.save_base(
  File "C:\Users\Sagacity\AppData\Local\Programs\Python\Python312\Lib\site-packages\django\db\models\base.py", line 924, in save_base
    post_save.send(
  File "C:\Users\Sagacity\AppData\Local\Programs\Python\Python312\Lib\site-packages\django\dispatch\dispatcher.py", line 189, in send
    response = receiver(signal=self, sender=sender, **named)
               ^^^^^^^^^^^^^^^^^^^^^^^^^^^^^^^^^^^^^^^^^^^^^
  File "C:\Users\Sagacity\Desktop\Project\TMS\transportation-management-system-backend\invoice\db_access\invoice.py", line 42, in send_notification_on_quotation_movement
    ).send_notification([created_by])
      ^^^^^^^^^^^^^^^^^^^^^^^^^^^^^^^
  File "C:\Users\Sagacity\Desktop\Project\TMS\transportation-management-system-backend\notification\helper.py", line 38, in send_notification
    notification = self.__create()
                   ^^^^^^^^^^^^^^^
  File "C:\Users\Sagacity\Desktop\Project\TMS\transportation-management-system-backend\notification\helper.py", line 18, in __create
    return self.manager.create(
           ^^^^^^^^^^^^^^^^^^^^
  File "C:\Users\Sagacity\Desktop\Project\TMS\transportation-management-system-backend\base\db_access\manager.py", line 343, in create
    return self.model.objects.create(**data)
           ^^^^^^^^^^^^^^^^^^^^^^^^^^^^^^^^^
  File "C:\Users\Sagacity\AppData\Local\Programs\Python\Python312\Lib\site-packages\django\db\models\manager.py", line 87, in manager_method
    return getattr(self.get_queryset(), name)(*args, **kwargs)
           ^^^^^^^^^^^^^^^^^^^^^^^^^^^^^^^^^^^^^^^^^^^^^^^^^^^
  File "C:\Users\Sagacity\AppData\Local\Programs\Python\Python312\Lib\site-packages\django\db\models\query.py", line 679, in create
    obj.save(force_insert=True, using=self.db)
  File "C:\Users\Sagacity\AppData\Local\Programs\Python\Python312\Lib\site-packages\django\db\models\base.py", line 822, in save
    self.save_base(
  File "C:\Users\Sagacity\AppData\Local\Programs\Python\Python312\Lib\site-packages\django\db\models\base.py", line 909, in save_base
    updated = self._save_table(
              ^^^^^^^^^^^^^^^^^
  File "C:\Users\Sagacity\AppData\Local\Programs\Python\Python312\Lib\site-packages\django\db\models\base.py", line 1071, in _save_table
    results = self._do_insert(
              ^^^^^^^^^^^^^^^^
  File "C:\Users\Sagacity\AppData\Local\Programs\Python\Python312\Lib\site-packages\django\db\models\base.py", line 1112, in _do_insert
    return manager._insert(
           ^^^^^^^^^^^^^^^^
  File "C:\Users\Sagacity\AppData\Local\Programs\Python\Python312\Lib\site-packages\django\db\models\manager.py", line 87, in manager_method
    return getattr(self.get_queryset(), name)(*args, **kwargs)
           ^^^^^^^^^^^^^^^^^^^^^^^^^^^^^^^^^^^^^^^^^^^^^^^^^^^
  File "C:\Users\Sagacity\AppData\Local\Programs\Python\Python312\Lib\site-packages\django\db\models\query.py", line 1847, in _insert
    return query.get_compiler(using=using).execute_sql(returning_fields)
           ^^^^^^^^^^^^^^^^^^^^^^^^^^^^^^^^^^^^^^^^^^^^^^^^^^^^^^^^^^^^^
  File "C:\Users\Sagacity\AppData\Local\Programs\Python\Python312\Lib\site-packages\django\db\models\sql\compiler.py", line 1823, in execute_sql
    cursor.execute(sql, params)
  File "C:\Users\Sagacity\AppData\Local\Programs\Python\Python312\Lib\site-packages\django\db\backends\utils.py", line 122, in execute
    return super().execute(sql, params)
           ^^^^^^^^^^^^^^^^^^^^^^^^^^^^
  File "C:\Users\Sagacity\AppData\Local\Programs\Python\Python312\Lib\site-packages\django\db\backends\utils.py", line 79, in execute
    return self._execute_with_wrappers(
           ^^^^^^^^^^^^^^^^^^^^^^^^^^^^
  File "C:\Users\Sagacity\AppData\Local\Programs\Python\Python312\Lib\site-packages\django\db\backends\utils.py", line 92, in _execute_with_wrappers
    return executor(sql, params, many, context)
           ^^^^^^^^^^^^^^^^^^^^^^^^^^^^^^^^^^^^
  File "C:\Users\Sagacity\AppData\Local\Programs\Python\Python312\Lib\site-packages\django\db\backends\utils.py", line 100, in _execute
    with self.db.wrap_database_errors:
  File "C:\Users\Sagacity\AppData\Local\Programs\Python\Python312\Lib\site-packages\django\db\utils.py", line 91, in __exit__
    raise dj_exc_value.with_traceback(traceback) from exc_value
  File "C:\Users\Sagacity\AppData\Local\Programs\Python\Python312\Lib\site-packages\django\db\backends\utils.py", line 105, in _execute
    return self.cursor.execute(sql, params)
           ^^^^^^^^^^^^^^^^^^^^^^^^^^^^^^^^
  File "C:\Users\Sagacity\AppData\Local\Programs\Python\Python312\Lib\site-packages\django\db\backends\sqlite3\base.py", line 329, in execute
    return super().execute(query, params)
           ^^^^^^^^^^^^^^^^^^^^^^^^^^^^^^
django.db.utils.OperationalError: no such table: notification

---------------------------------------------------------------------------------------------------------------------
